<sdf version='1.7'>
  <world name='default'>
    <light name='sun' type='directional'>
      <cast_shadows>1</cast_shadows>
      <pose>0 0 10 0 -0 0</pose>
      <diffuse>0.8 0.8 0.8 1</diffuse>
      <specular>0.2 0.2 0.2 1</specular>
      <attenuation>
        <range>1000</range>
        <constant>0.9</constant>
        <linear>0.01</linear>
        <quadratic>0.001</quadratic>
      </attenuation>
      <direction>-0.5 0.1 -0.9</direction>
      <spot>
        <inner_angle>0</inner_angle>
        <outer_angle>0</outer_angle>
        <falloff>0</falloff>
      </spot>
    </light>
    <model name='ground_plane'>
      <static>1</static>
      <link name='link'>
        <collision name='collision'>
          <geometry>
            <plane>
              <normal>0 0 1</normal>
              <size>100 100</size>
            </plane>
          </geometry>
          <surface>
            <friction>
              <ode>
                <mu>100</mu>
                <mu2>50</mu2>
              </ode>
              <torsional>
                <ode/>
              </torsional>
            </friction>
            <contact>
              <ode/>
            </contact>
            <bounce/>
          </surface>
          <max_contacts>10</max_contacts>
        </collision>
        <visual name='visual'>
          <cast_shadows>0</cast_shadows>
          <geometry>
            <plane>
              <normal>0 0 1</normal>
              <size>100 100</size>
            </plane>
          </geometry>
          <material>
            <script>
              <uri>file://media/materials/scripts/gazebo.material</uri>
              <name>Gazebo/Grey</name>
            </script>
          </material>
        </visual>
        <self_collide>0</self_collide>
        <enable_wind>0</enable_wind>
        <kinematic>0</kinematic>
      </link>
    </model>
    <gravity>0 0 -9.8</gravity>
    <magnetic_field>6e-06 2.3e-05 -4.2e-05</magnetic_field>
    <atmosphere type='adiabatic'/>
    <physics type='ode'>
      <max_step_size>0.001</max_step_size>
      <real_time_factor>1</real_time_factor>
      <real_time_update_rate>1000</real_time_update_rate>
    </physics>
    <scene>
      <ambient>0.4 0.4 0.4 1</ambient>
      <background>0.7 0.7 0.7 1</background>
      <shadows>1</shadows>
    </scene>
    <audio>
      <device>default</device>
    </audio>
    <wind/>
    <spherical_coordinates>
      <surface_model>EARTH_WGS84</surface_model>
      <latitude_deg>0</latitude_deg>
      <longitude_deg>0</longitude_deg>
      <elevation>0</elevation>
      <heading_deg>0</heading_deg>
    </spherical_coordinates>
    <model name='robotic_arm'>
      <link name='base_link'>
        <inertial>
          <pose>0.014852 -0.019978 0.036859 0 -0 0</pose>
          <mass>0.421359</mass>
          <inertia>
            <ixx>0.000248406</ixx>
            <ixy>1.21688e-05</ixy>
            <ixz>-3.66607e-05</ixz>
            <iyy>0.000339394</iyy>
            <iyz>4.69539e-05</iyz>
            <izz>0.000197969</izz>
          </inertia>
        </inertial>
        <collision name='base_link_collision'>
          <pose>0 0 0 0 -0 0</pose>
          <geometry>
            <mesh>
              <scale>0.001 0.001 0.001</scale>
              <uri>model://fivedofarmzup_description/meshes/base_link.stl</uri>
            </mesh>
          </geometry>
          <surface>
            <contact>
              <ode/>
            </contact>
            <friction>
              <ode>
                <mu>0.2</mu>
                <mu2>0.2</mu2>
              </ode>
              <torsional>
                <ode/>
              </torsional>
            </friction>
            <bounce/>
          </surface>
          <max_contacts>10</max_contacts>
        </collision>
        <collision name='base_link_fixed_joint_lump__Servo_Bracket_-_U_Shaped_Defaut_v1_1_collision_1'>
          <pose>0 0 0 0 -0 0</pose>
          <geometry>
            <mesh>
              <scale>0.001 0.001 0.001</scale>
              <uri>model://fivedofarmzup_description/meshes/Servo_Bracket_-_U_Shaped_Defaut_v1_1.stl</uri>
            </mesh>
          </geometry>
          <surface>
            <contact>
              <ode/>
            </contact>
            <friction>
              <ode>
                <mu>0.2</mu>
                <mu2>0.2</mu2>
              </ode>
              <torsional>
                <ode/>
              </torsional>
            </friction>
            <bounce/>
          </surface>
          <max_contacts>10</max_contacts>
        </collision>
        <collision name='base_link_fixed_joint_lump__Standard_Servo__1501MG__v2_1_collision_2'>
          <pose>0 0 0 0 -0 0</pose>
          <geometry>
            <mesh>
              <scale>0.001 0.001 0.001</scale>
              <uri>model://fivedofarmzup_description/meshes/Standard_Servo__1501MG__v2_1.stl</uri>
            </mesh>
          </geometry>
          <surface>
            <contact>
              <ode/>
            </contact>
            <friction>
              <ode>
                <mu>0.2</mu>
                <mu2>0.2</mu2>
              </ode>
              <torsional>
                <ode/>
              </torsional>
            </friction>
            <bounce/>
          </surface>
          <max_contacts>10</max_contacts>
        </collision>
        <visual name='base_link_visual'>
          <pose>0 0 0 0 -0 0</pose>
          <geometry>
            <mesh>
              <scale>0.001 0.001 0.001</scale>
              <uri>model://fivedofarmzup_description/meshes/base_link.stl</uri>
            </mesh>
          </geometry>
          <material>
            <script>
              <name>Gazebo/Green</name>
              <uri>file://media/materials/scripts/gazebo.material</uri>
            </script>
          </material>
        </visual>
        <visual name='base_link_fixed_joint_lump__Servo_Bracket_-_U_Shaped_Defaut_v1_1_visual_1'>
          <pose>0 0 0 0 -0 0</pose>
          <geometry>
            <mesh>
              <scale>0.001 0.001 0.001</scale>
              <uri>model://fivedofarmzup_description/meshes/Servo_Bracket_-_U_Shaped_Defaut_v1_1.stl</uri>
            </mesh>
          </geometry>
          <material>
            <script>
              <name>Gazebo/Red</name>
              <uri>file://media/materials/scripts/gazebo.material</uri>
            </script>
          </material>
        </visual>
        <visual name='base_link_fixed_joint_lump__Standard_Servo__1501MG__v2_1_visual_2'>
          <pose>0 0 0 0 -0 0</pose>
          <geometry>
            <mesh>
              <scale>0.001 0.001 0.001</scale>
              <uri>model://fivedofarmzup_description/meshes/Standard_Servo__1501MG__v2_1.stl</uri>
            </mesh>
          </geometry>
          <material>
            <script>
              <name>Gazebo/Black</name>
              <uri>file://media/materials/scripts/gazebo.material</uri>
            </script>
          </material>
        </visual>
        <self_collide>1</self_collide>
        <gravity>1</gravity>
        <self_collide>1</self_collide>
        <gravity>1</gravity>
        <self_collide>1</self_collide>
        <gravity>1</gravity>
        <enable_wind>0</enable_wind>
        <kinematic>0</kinematic>
      </link>
      <joint name='Revolute 3' type='revolute'>
        <pose relative_to='base_link'>0.027957 -0.025381 0.075787 0 -0 0</pose>
        <parent>base_link</parent>
        <child>Servo_Bracket_-_U_Shaped_Defaut_v1_2</child>
        <axis>
          <xyz>0 0 1</xyz>
          <limit>
            <lower>-1e+16</lower>
            <upper>1e+16</upper>
          </limit>
          <dynamics>
            <spring_reference>0</spring_reference>
            <spring_stiffness>0</spring_stiffness>
          </dynamics>
        </axis>
      </joint>
      <link name='Servo_Bracket_-_U_Shaped_Defaut_v1_2'>
        <pose relative_to='Revolute 3'>0 0 0 0 -0 0</pose>
        <inertial>
          <pose>-0.001997 0.001852 0.013266 0 -0 0</pose>
          <mass>0.28286</mass>
          <inertia>
            <ixx>5.38655e-05</ixx>
            <ixy>-2.33366e-06</ixy>
            <ixz>-1.08746e-06</ixz>
            <iyy>5.62399e-05</iyy>
            <iyz>3.97152e-07</iyz>
            <izz>8.46049e-05</izz>
          </inertia>
        </inertial>
        <collision name='Servo_Bracket_-_U_Shaped_Defaut_v1_2_collision'>
          <pose>-0.027957 0.025381 -0.075787 0 -0 0</pose>
          <geometry>
            <mesh>
              <scale>0.001 0.001 0.001</scale>
              <uri>model://fivedofarmzup_description/meshes/Servo_Bracket_-_U_Shaped_Defaut_v1_2.stl</uri>
            </mesh>
          </geometry>
          <surface>
            <contact>
              <ode/>
            </contact>
            <friction>
              <ode>
                <mu>0.2</mu>
                <mu2>0.2</mu2>
              </ode>
              <torsional>
                <ode/>
              </torsional>
            </friction>
            <bounce/>
          </surface>
          <max_contacts>10</max_contacts>
        </collision>
        <collision name='Servo_Bracket_-_U_Shaped_Defaut_v1_2_fixed_joint_lump__Standard_Servo__1501MG__v2_2_collision_1'>
          <pose>-0.027957 0.025381 -0.075787 0 -0 0</pose>
          <geometry>
            <mesh>
              <scale>0.001 0.001 0.001</scale>
              <uri>model://fivedofarmzup_description/meshes/Standard_Servo__1501MG__v2_2.stl</uri>
            </mesh>
          </geometry>
          <surface>
            <contact>
              <ode/>
            </contact>
            <friction>
              <ode>
                <mu>0.2</mu>
                <mu2>0.2</mu2>
              </ode>
              <torsional>
                <ode/>
              </torsional>
            </friction>
            <bounce/>
          </surface>
          <max_contacts>10</max_contacts>
        </collision>
        <visual name='Servo_Bracket_-_U_Shaped_Defaut_v1_2_visual'>
          <pose>-0.027957 0.025381 -0.075787 0 -0 0</pose>
          <geometry>
            <mesh>
              <scale>0.001 0.001 0.001</scale>
              <uri>model://fivedofarmzup_description/meshes/Servo_Bracket_-_U_Shaped_Defaut_v1_2.stl</uri>
            </mesh>
          </geometry>
          <material>
            <script>
              <name>Gazebo/Red</name>
              <uri>file://media/materials/scripts/gazebo.material</uri>
            </script>
          </material>
        </visual>
        <visual name='Servo_Bracket_-_U_Shaped_Defaut_v1_2_fixed_joint_lump__Standard_Servo__1501MG__v2_2_visual_1'>
          <pose>-0.027957 0.025381 -0.075787 0 -0 0</pose>
          <geometry>
            <mesh>
              <scale>0.001 0.001 0.001</scale>
              <uri>model://fivedofarmzup_description/meshes/Standard_Servo__1501MG__v2_2.stl</uri>
            </mesh>
          </geometry>
          <material>
            <script>
              <name>Gazebo/Black</name>
              <uri>file://media/materials/scripts/gazebo.material</uri>
            </script>
          </material>
        </visual>
        <self_collide>1</self_collide>
        <gravity>1</gravity>
        <self_collide>1</self_collide>
        <gravity>1</gravity>
        <enable_wind>0</enable_wind>
        <kinematic>0</kinematic>
      </link>
      <joint name='Revolute 5' type='revolute'>
        <pose relative_to='Servo_Bracket_-_U_Shaped_Defaut_v1_2'>0.025087 -0.005624 0.014325 0 -0 0</pose>
        <parent>Servo_Bracket_-_U_Shaped_Defaut_v1_2</parent>
        <child>Servo_Bracket_-_U_Shaped_bis_Defaut_v1_1</child>
        <axis>
          <xyz>-0.808932 0.587903 0</xyz>
          <limit>
            <lower>-1.5708</lower>
            <upper>1.5708</upper>
            <effort>100</effort>
            <velocity>100</velocity>
          </limit>
          <dynamics>
            <spring_reference>0</spring_reference>
            <spring_stiffness>0</spring_stiffness>
          </dynamics>
        </axis>
      </joint>
      <link name='Servo_Bracket_-_U_Shaped_bis_Defaut_v1_1'>
        <pose relative_to='Revolute 5'>0 0 0 0 -0 0</pose>
        <inertial>
          <pose>-0.021032 0.015286 0.044906 0 -0 0</pose>
          <mass>0.110048</mass>
          <inertia>
            <ixx>8.99116e-05</ixx>
            <ixy>2.6e-05</ixy>
            <ixz>-1.3932e-17</ixz>
            <iyy>0.000106912</iyy>
            <iyz>3.32037e-18</iyz>
            <izz>6.7e-05</izz>
          </inertia>
        </inertial>
        <collision name='Servo_Bracket_-_U_Shaped_bis_Defaut_v1_1_collision'>
          <pose>-0.053044 0.031005 -0.090112 0 -0 0</pose>
          <geometry>
            <mesh>
              <scale>0.001 0.001 0.001</scale>
              <uri>model://fivedofarmzup_description/meshes/Servo_Bracket_-_U_Shaped_bis_Defaut_v1_1.stl</uri>
            </mesh>
          </geometry>
          <surface>
            <contact>
              <ode/>
            </contact>
            <friction>
              <ode>
                <mu>0.2</mu>
                <mu2>0.2</mu2>
              </ode>
              <torsional>
                <ode/>
              </torsional>
            </friction>
            <bounce/>
          </surface>
          <max_contacts>10</max_contacts>
        </collision>
        <collision name='Servo_Bracket_-_U_Shaped_bis_Defaut_v1_1_fixed_joint_lump__U_Bracket_Defaut_v1_1_collision_1'>
          <pose>-0.053044 0.031005 -0.090112 0 -0 0</pose>
          <geometry>
            <mesh>
              <scale>0.001 0.001 0.001</scale>
              <uri>model://fivedofarmzup_description/meshes/U_Bracket_Defaut_v1_1.stl</uri>
            </mesh>
          </geometry>
          <surface>
            <contact>
              <ode/>
            </contact>
            <friction>
              <ode>
                <mu>0.2</mu>
                <mu2>0.2</mu2>
              </ode>
              <torsional>
                <ode/>
              </torsional>
            </friction>
            <bounce/>
          </surface>
          <max_contacts>10</max_contacts>
        </collision>
        <visual name='Servo_Bracket_-_U_Shaped_bis_Defaut_v1_1_visual'>
          <pose>-0.053044 0.031005 -0.090112 0 -0 0</pose>
          <geometry>
            <mesh>
              <scale>0.001 0.001 0.001</scale>
              <uri>model://fivedofarmzup_description/meshes/Servo_Bracket_-_U_Shaped_bis_Defaut_v1_1.stl</uri>
            </mesh>
          </geometry>
          <material>
            <script>
              <name>Gazebo/Blue</name>
              <uri>file://media/materials/scripts/gazebo.material</uri>
            </script>
          </material>
        </visual>
        <visual name='Servo_Bracket_-_U_Shaped_bis_Defaut_v1_1_fixed_joint_lump__U_Bracket_Defaut_v1_1_visual_1'>
          <pose>-0.053044 0.031005 -0.090112 0 -0 0</pose>
          <geometry>
            <mesh>
              <scale>0.001 0.001 0.001</scale>
              <uri>model://fivedofarmzup_description/meshes/U_Bracket_Defaut_v1_1.stl</uri>
            </mesh>
          </geometry>
          <material>
            <script>
              <name>Gazebo/Blue</name>
              <uri>file://media/materials/scripts/gazebo.material</uri>
            </script>
          </material>
        </visual>
        <self_collide>1</self_collide>
        <gravity>1</gravity>
        <self_collide>1</self_collide>
        <gravity>1</gravity>
        <enable_wind>0</enable_wind>
        <kinematic>0</kinematic>
      </link>
      <joint name='Revolute 7' type='revolute'>
        <pose relative_to='Servo_Bracket_-_U_Shaped_bis_Defaut_v1_1'>0 0 0.083 0 -0 0</pose>
        <parent>Servo_Bracket_-_U_Shaped_bis_Defaut_v1_1</parent>
        <child>Standard_Servo__1501MG__v2_3</child>
        <axis>
          <xyz>-0.808932 0.587903 0</xyz>
          <limit>
            <lower>3.14159</lower>
            <upper>6.28318</upper>
            <effort>100</effort>
            <velocity>100</velocity>
          </limit>
          <dynamics>
            <spring_reference>0</spring_reference>
            <spring_stiffness>0</spring_stiffness>
          </dynamics>
        </axis>
      </joint>
      <link name='Standard_Servo__1501MG__v2_3'>
        <pose relative_to='Revolute 7'>0 0 0 0 -0 0</pose>
        <inertial>
          <pose>-0.023792 0.014637 0.016829 0 -0 0</pose>
          <mass>0.346893</mass>
          <inertia>
            <ixx>0.000167242</ixx>
            <ixy>2.1181e-05</ixy>
            <ixz>2.7773e-05</ixz>
            <iyy>0.000183782</iyy>
            <iyz>9.00063e-06</iyz>
            <izz>9.0555e-05</izz>
          </inertia>
        </inertial>
        <collision name='Standard_Servo__1501MG__v2_3_collision'>
          <pose>-0.053044 0.031005 -0.173112 0 -0 0</pose>
          <geometry>
            <mesh>
              <scale>0.001 0.001 0.001</scale>
              <uri>model://fivedofarmzup_description/meshes/Standard_Servo__1501MG__v2_3.stl</uri>
            </mesh>
          </geometry>
          <surface>
            <contact>
              <ode/>
            </contact>
            <friction>
              <ode>
                <mu>0.2</mu>
                <mu2>0.2</mu2>
              </ode>
              <torsional>
                <ode/>
              </torsional>
            </friction>
            <bounce/>
          </surface>
          <max_contacts>10</max_contacts>
        </collision>
        <collision name='Standard_Servo__1501MG__v2_3_fixed_joint_lump__Servo_Bracket_-_U_Shaped_Defaut_v1_3_collision_1'>
          <pose>-0.053044 0.031005 -0.173112 0 -0 0</pose>
          <geometry>
            <mesh>
              <scale>0.001 0.001 0.001</scale>
              <uri>model://fivedofarmzup_description/meshes/Servo_Bracket_-_U_Shaped_Defaut_v1_3.stl</uri>
            </mesh>
          </geometry>
          <surface>
            <contact>
              <ode/>
            </contact>
            <friction>
              <ode>
                <mu>0.2</mu>
                <mu2>0.2</mu2>
              </ode>
              <torsional>
                <ode/>
              </torsional>
            </friction>
            <bounce/>
          </surface>
          <max_contacts>10</max_contacts>
        </collision>
        <collision name='Standard_Servo__1501MG__v2_3_fixed_joint_lump__Servo_Bracket_-_Corner_Mount_Defaut_v1_1_collision_2'>
          <pose>-0.053044 0.031005 -0.173112 0 -0 0</pose>
          <geometry>
            <mesh>
              <scale>0.001 0.001 0.001</scale>
              <uri>model://fivedofarmzup_description/meshes/Servo_Bracket_-_Corner_Mount_Defaut_v1_1.stl</uri>
            </mesh>
          </geometry>
          <surface>
            <contact>
              <ode/>
            </contact>
            <friction>
              <ode>
                <mu>0.2</mu>
                <mu2>0.2</mu2>
              </ode>
              <torsional>
                <ode/>
              </torsional>
            </friction>
            <bounce/>
          </surface>
          <max_contacts>10</max_contacts>
        </collision>
        <collision name='Standard_Servo__1501MG__v2_3_fixed_joint_lump__U_Bracket_Defaut_v1_2_collision_3'>
          <pose>-0.053044 0.031005 -0.173112 0 -0 0</pose>
          <geometry>
            <mesh>
              <scale>0.001 0.001 0.001</scale>
              <uri>model://fivedofarmzup_description/meshes/U_Bracket_Defaut_v1_2.stl</uri>
            </mesh>
          </geometry>
          <surface>
            <contact>
              <ode/>
            </contact>
            <friction>
              <ode>
                <mu>0.2</mu>
                <mu2>0.2</mu2>
              </ode>
              <torsional>
                <ode/>
              </torsional>
            </friction>
            <bounce/>
          </surface>
          <max_contacts>10</max_contacts>
        </collision>
        <visual name='Standard_Servo__1501MG__v2_3_visual'>
          <pose>-0.053044 0.031005 -0.173112 0 -0 0</pose>
          <geometry>
            <mesh>
              <scale>0.001 0.001 0.001</scale>
              <uri>model://fivedofarmzup_description/meshes/Standard_Servo__1501MG__v2_3.stl</uri>
            </mesh>
          </geometry>
          <material>
            <script>
              <name>Gazebo/Blue</name>
              <uri>file://media/materials/scripts/gazebo.material</uri>
            </script>
          </material>
        </visual>
        <visual name='Standard_Servo__1501MG__v2_3_fixed_joint_lump__Servo_Bracket_-_U_Shaped_Defaut_v1_3_visual_1'>
          <pose>-0.053044 0.031005 -0.173112 0 -0 0</pose>
          <geometry>
            <mesh>
              <scale>0.001 0.001 0.001</scale>
              <uri>model://fivedofarmzup_description/meshes/Servo_Bracket_-_U_Shaped_Defaut_v1_3.stl</uri>
            </mesh>
          </geometry>
          <material>
            <script>
              <name>Gazebo/Blue</name>
              <uri>file://media/materials/scripts/gazebo.material</uri>
            </script>
          </material>
        </visual>
        <visual name='Standard_Servo__1501MG__v2_3_fixed_joint_lump__Servo_Bracket_-_Corner_Mount_Defaut_v1_1_visual_2'>
          <pose>-0.053044 0.031005 -0.173112 0 -0 0</pose>
          <geometry>
            <mesh>
              <scale>0.001 0.001 0.001</scale>
              <uri>model://fivedofarmzup_description/meshes/Servo_Bracket_-_Corner_Mount_Defaut_v1_1.stl</uri>
            </mesh>
          </geometry>
          <material>
            <script>
              <name>Gazebo/Blue</name>
              <uri>file://media/materials/scripts/gazebo.material</uri>
            </script>
          </material>
        </visual>
        <visual name='Standard_Servo__1501MG__v2_3_fixed_joint_lump__U_Bracket_Defaut_v1_2_visual_3'>
          <pose>-0.053044 0.031005 -0.173112 0 -0 0</pose>
          <geometry>
            <mesh>
              <scale>0.001 0.001 0.001</scale>
              <uri>model://fivedofarmzup_description/meshes/U_Bracket_Defaut_v1_2.stl</uri>
            </mesh>
          </geometry>
          <material>
            <script>
              <name>Gazebo/Blue</name>
              <uri>file://media/materials/scripts/gazebo.material</uri>
            </script>
          </material>
        </visual>
        <self_collide>1</self_collide>
        <gravity>1</gravity>
        <self_collide>1</self_collide>
        <gravity>1</gravity>
        <self_collide>1</self_collide>
        <gravity>1</gravity>
        <self_collide>1</self_collide>
        <gravity>1</gravity>
        <enable_wind>0</enable_wind>
        <kinematic>0</kinematic>
      </link>
      <joint name='Revolute 11' type='revolute'>
        <pose relative_to='Standard_Servo__1501MG__v2_3'>-0.057157 0.023072 0.07064 0 -0 0</pose>
        <parent>Standard_Servo__1501MG__v2_3</parent>
        <child>Standard_Servo__1501MG__v2_4</child>
        <axis>
          <xyz>-0.808932 0.587903 0</xyz>
          <limit>
            <lower>-1.5708</lower>
            <upper>1.5708</upper>
            <effort>100</effort>
            <velocity>100</velocity>
          </limit>
          <dynamics>
            <spring_reference>0</spring_reference>
            <spring_stiffness>0</spring_stiffness>
          </dynamics>
        </axis>
      </joint>
      <link name='Standard_Servo__1501MG__v2_4'>
        <pose relative_to='Revolute 11'>0 0 0 0 -0 0</pose>
        <inertial>
          <pose>0.023489 -0.026381 0.036772 0 -0 0</pose>
          <mass>0.584388</mass>
          <inertia>
            <ixx>0.00060524</ixx>
            <ixy>4.13477e-05</ixy>
            <ixz>-3.30213e-05</ixz>
            <iyy>0.00056653</iyy>
            <iyz>0.000168949</iyz>
            <izz>0.000181967</izz>
          </inertia>
        </inertial>
        <collision name='Standard_Servo__1501MG__v2_4_collision'>
          <pose>0.004113 0.007933 -0.243752 0 -0 0</pose>
          <geometry>
            <mesh>
              <scale>0.001 0.001 0.001</scale>
              <uri>model://fivedofarmzup_description/meshes/Standard_Servo__1501MG__v2_4.stl</uri>
            </mesh>
          </geometry>
          <surface>
            <contact>
              <ode/>
            </contact>
            <friction>
              <ode>
                <mu>0.2</mu>
                <mu2>0.2</mu2>
              </ode>
              <torsional>
                <ode/>
              </torsional>
            </friction>
            <bounce/>
          </surface>
          <max_contacts>10</max_contacts>
        </collision>
        <collision name='Standard_Servo__1501MG__v2_4_fixed_joint_lump__Servo_Bracket_-_U_Shaped_Defaut_v1_4_collision_1'>
          <pose>0.004113 0.007933 -0.243752 0 -0 0</pose>
          <geometry>
            <mesh>
              <scale>0.001 0.001 0.001</scale>
              <uri>model://fivedofarmzup_description/meshes/Servo_Bracket_-_U_Shaped_Defaut_v1_4.stl</uri>
            </mesh>
          </geometry>
          <surface>
            <contact>
              <ode/>
            </contact>
            <friction>
              <ode>
                <mu>0.2</mu>
                <mu2>0.2</mu2>
              </ode>
              <torsional>
                <ode/>
              </torsional>
            </friction>
            <bounce/>
          </surface>
          <max_contacts>10</max_contacts>
        </collision>
        <collision name='Standard_Servo__1501MG__v2_4_fixed_joint_lump__Servo_Bracket_-_Corner_Mount_Defaut_v1_2_collision_2'>
          <pose>0.004113 0.007933 -0.243752 0 -0 0</pose>
          <geometry>
            <mesh>
              <scale>0.001 0.001 0.001</scale>
              <uri>model://fivedofarmzup_description/meshes/Servo_Bracket_-_Corner_Mount_Defaut_v1_2.stl</uri>
            </mesh>
          </geometry>
          <surface>
            <contact>
              <ode/>
            </contact>
            <friction>
              <ode>
                <mu>0.2</mu>
                <mu2>0.2</mu2>
              </ode>
              <torsional>
                <ode/>
              </torsional>
            </friction>
            <bounce/>
          </surface>
          <max_contacts>10</max_contacts>
        </collision>
        <collision name='Standard_Servo__1501MG__v2_4_fixed_joint_lump__Servo_Bracket_-_U_Shaped_Defaut_v1_5_collision_3'>
          <pose>0.004113 0.007933 -0.243752 0 -0 0</pose>
          <geometry>
            <mesh>
              <scale>0.001 0.001 0.001</scale>
              <uri>model://fivedofarmzup_description/meshes/Servo_Bracket_-_U_Shaped_Defaut_v1_5.stl</uri>
            </mesh>
          </geometry>
          <surface>
            <contact>
              <ode/>
            </contact>
            <friction>
              <ode>
                <mu>0.2</mu>
                <mu2>0.2</mu2>
              </ode>
              <torsional>
                <ode/>
              </torsional>
            </friction>
            <bounce/>
          </surface>
          <max_contacts>10</max_contacts>
        </collision>
        <collision name='Standard_Servo__1501MG__v2_4_fixed_joint_lump__Standard_Servo__1501MG__v2_5_collision_4'>
          <pose>0.004113 0.007933 -0.243752 0 -0 0</pose>
          <geometry>
            <mesh>
              <scale>0.001 0.001 0.001</scale>
              <uri>model://fivedofarmzup_description/meshes/Standard_Servo__1501MG__v2_5.stl</uri>
            </mesh>
          </geometry>
          <surface>
            <contact>
              <ode/>
            </contact>
            <friction>
              <ode>
                <mu>0.2</mu>
                <mu2>0.2</mu2>
              </ode>
              <torsional>
                <ode/>
              </torsional>
            </friction>
            <bounce/>
          </surface>
          <max_contacts>10</max_contacts>
        </collision>
        <visual name='Standard_Servo__1501MG__v2_4_visual'>
          <pose>0.004113 0.007933 -0.243752 0 -0 0</pose>
          <geometry>
            <mesh>
              <scale>0.001 0.001 0.001</scale>
              <uri>model://fivedofarmzup_description/meshes/Standard_Servo__1501MG__v2_4.stl</uri>
            </mesh>
          </geometry>
          <material>
            <script>
              <name>Gazebo/Blue</name>
              <uri>file://media/materials/scripts/gazebo.material</uri>
            </script>
          </material>
        </visual>
        <visual name='Standard_Servo__1501MG__v2_4_fixed_joint_lump__Servo_Bracket_-_U_Shaped_Defaut_v1_4_visual_1'>
          <pose>0.004113 0.007933 -0.243752 0 -0 0</pose>
          <geometry>
            <mesh>
              <scale>0.001 0.001 0.001</scale>
              <uri>model://fivedofarmzup_description/meshes/Servo_Bracket_-_U_Shaped_Defaut_v1_4.stl</uri>
            </mesh>
          </geometry>
          <material>
            <script>
              <name>Gazebo/Blue</name>
              <uri>file://media/materials/scripts/gazebo.material</uri>
            </script>
          </material>
        </visual>
        <visual name='Standard_Servo__1501MG__v2_4_fixed_joint_lump__Servo_Bracket_-_Corner_Mount_Defaut_v1_2_visual_2'>
          <pose>0.004113 0.007933 -0.243752 0 -0 0</pose>
          <geometry>
            <mesh>
              <scale>0.001 0.001 0.001</scale>
              <uri>model://fivedofarmzup_description/meshes/Servo_Bracket_-_Corner_Mount_Defaut_v1_2.stl</uri>
            </mesh>
          </geometry>
          <material>
            <script>
              <name>Gazebo/Blue</name>
              <uri>file://media/materials/scripts/gazebo.material</uri>
            </script>
          </material>
        </visual>
        <visual name='Standard_Servo__1501MG__v2_4_fixed_joint_lump__Servo_Bracket_-_U_Shaped_Defaut_v1_5_visual_3'>
          <pose>0.004113 0.007933 -0.243752 0 -0 0</pose>
          <geometry>
            <mesh>
              <scale>0.001 0.001 0.001</scale>
              <uri>model://fivedofarmzup_description/meshes/Servo_Bracket_-_U_Shaped_Defaut_v1_5.stl</uri>
            </mesh>
          </geometry>
          <material>
            <script>
              <name>Gazebo/Blue</name>
              <uri>file://media/materials/scripts/gazebo.material</uri>
            </script>
          </material>
        </visual>
        <visual name='Standard_Servo__1501MG__v2_4_fixed_joint_lump__Standard_Servo__1501MG__v2_5_visual_4'>
          <pose>0.004113 0.007933 -0.243752 0 -0 0</pose>
          <geometry>
            <mesh>
              <scale>0.001 0.001 0.001</scale>
              <uri>model://fivedofarmzup_description/meshes/Standard_Servo__1501MG__v2_5.stl</uri>
            </mesh>
          </geometry>
          <material>
            <script>
              <name>Gazebo/Blue</name>
              <uri>file://media/materials/scripts/gazebo.material</uri>
            </script>
          </material>
        </visual>
        <self_collide>1</self_collide>
        <gravity>1</gravity>
        <self_collide>1</self_collide>
        <gravity>1</gravity>
        <self_collide>1</self_collide>
        <gravity>1</gravity>
        <self_collide>1</self_collide>
        <gravity>1</gravity>
        <self_collide>1</self_collide>
        <gravity>1</gravity>
        <enable_wind>0</enable_wind>
        <kinematic>0</kinematic>
      </link>
      <joint name='Revolute 19' type='revolute'>
        <pose relative_to='Standard_Servo__1501MG__v2_4'>0.015216 -0.035026 0.089936 0 -0 0</pose>
        <parent>Standard_Servo__1501MG__v2_4</parent>
        <child>Gripz_v2_1</child>
        <axis>
          <xyz>-0.127014 -0.174766 0.976383</xyz>
          <limit>
            <lower>-1.5708</lower>
            <upper>1.5708</upper>
            <effort>100</effort>
            <velocity>100</velocity>
          </limit>
          <dynamics>
            <spring_reference>0</spring_reference>
            <spring_stiffness>0</spring_stiffness>
          </dynamics>
        </axis>
      </joint>
      <link name='Gripz_v2_1'>
        <pose relative_to='Revolute 19'>0 0 0 0 -0 0</pose>
        <inertial>
          <pose>0.004728 0.00382 0.016617 0 -0 0</pose>
          <mass>0.263495</mass>
          <inertia>
            <ixx>5.2e-05</ixx>
            <ixy>0</ixy>
            <ixz>-4e-06</ixz>
            <iyy>5.2e-05</iyy>
            <iyz>-6e-06</iyz>
            <izz>8e-05</izz>
          </inertia>
        </inertial>
        <collision name='Gripz_v2_1_collision'>
          <pose>-0.011103 0.042959 -0.333688 0 -0 0</pose>
          <geometry>
            <mesh>
              <scale>0.001 0.001 0.001</scale>
              <uri>model://fivedofarmzup_description/meshes/Gripz_v2_1.stl</uri>
            </mesh>
          </geometry>
          <surface>
            <contact>
              <ode/>
            </contact>
            <friction>
              <ode>
                <mu>0.2</mu>
                <mu2>0.2</mu2>
              </ode>
              <torsional>
                <ode/>
              </torsional>
            </friction>
            <bounce/>
          </surface>
          <max_contacts>10</max_contacts>
        </collision>
        <visual name='Gripz_v2_1_visual'>
          <pose>-0.011103 0.042959 -0.333688 0 -0 0</pose>
          <geometry>
            <mesh>
              <scale>0.001 0.001 0.001</scale>
              <uri>model://fivedofarmzup_description/meshes/Gripz_v2_1.stl</uri>
            </mesh>
          </geometry>
          <material>
            <script>
              <name>Gazebo/Blue</name>
              <uri>file://media/materials/scripts/gazebo.material</uri>
            </script>
          </material>
        </visual>
        <self_collide>1</self_collide>
        <gravity>1</gravity>
        <enable_wind>0</enable_wind>
        <kinematic>0</kinematic>
      </link>
      <joint name='Revolute 21' type='revolute'>
        <pose relative_to='Gripz_v2_1'>0.027015 0.017271 0.022455 0 -0 0</pose>
        <parent>Gripz_v2_1</parent>
        <child>left-gripper_v3_1</child>
        <axis>
          <xyz>0.574019 0.789827 0.216045</xyz>
          <limit>
            <effort>100</effort>
            <velocity>100</velocity>
            <lower>-1e+16</lower>
            <upper>1e+16</upper>
          </limit>
          <dynamics>
            <spring_reference>0</spring_reference>
            <spring_stiffness>0</spring_stiffness>
          </dynamics>
        </axis>
      </joint>
      <link name='left-gripper_v3_1'>
        <pose relative_to='Revolute 21'>0 0 0 0 -0 0</pose>
        <inertial>
          <pose>0.035149 -0.046275 0.034011 0 -0 0</pose>
          <mass>0.024857</mass>
          <inertia>
            <ixx>3.2e-05</ixx>
            <ixy>8e-06</ixy>
            <ixz>-9e-06</ixz>
            <iyy>2.9e-05</iyy>
            <iyz>1.3e-05</iyz>
            <izz>2e-05</izz>
          </inertia>
        </inertial>
        <collision name='left-gripper_v3_1_collision'>
          <pose>-0.038118 0.025688 -0.356143 0 -0 0</pose>
          <geometry>
            <mesh>
              <scale>0.001 0.001 0.001</scale>
              <uri>model://fivedofarmzup_description/meshes/left-gripper_v3_1.stl</uri>
            </mesh>
          </geometry>
          <surface>
            <contact>
              <ode/>
            </contact>
            <friction>
              <ode>
                <mu>0.2</mu>
                <mu2>0.2</mu2>
              </ode>
              <torsional>
                <ode/>
              </torsional>
            </friction>
            <bounce/>
          </surface>
          <max_contacts>10</max_contacts>
        </collision>
        <visual name='left-gripper_v3_1_visual'>
          <pose>-0.038118 0.025688 -0.356143 0 -0 0</pose>
          <geometry>
            <mesh>
              <scale>0.001 0.001 0.001</scale>
              <uri>model://fivedofarmzup_description/meshes/left-gripper_v3_1.stl</uri>
            </mesh>
          </geometry>
          <material>
            <script>
              <name>Gazebo/Blue</name>
              <uri>file://media/materials/scripts/gazebo.material</uri>
            </script>
          </material>
        </visual>
        <self_collide>1</self_collide>
        <gravity>1</gravity>
        <enable_wind>0</enable_wind>
        <kinematic>0</kinematic>
      </link>
      <joint name='Revolute 22' type='revolute'>
        <pose relative_to='Gripz_v2_1'>0.008043 0.031053 0.022479 0 -0 0</pose>
        <parent>Gripz_v2_1</parent>
        <child>right-gripper_v2_1</child>
        <axis>
          <xyz>0.574019 0.789827 0.216045</xyz>
          <limit>
            <lower>-1e+16</lower>
            <upper>1e+16</upper>
          </limit>
          <dynamics>
            <spring_reference>0</spring_reference>
            <spring_stiffness>0</spring_stiffness>
          </dynamics>
        </axis>
      </joint>
      <link name='right-gripper_v2_1'>
        <pose relative_to='Revolute 22'>0 0 0 0 -0 0</pose>
        <inertial>
          <pose>-0.059712 0.028651 0.012133 0 -0 0</pose>
          <mass>0.024857</mass>
          <inertia>
            <ixx>1.8e-05</ixx>
            <ixy>1.1e-05</ixy>
            <ixz>1.2e-05</ixz>
            <iyy>3.3e-05</iyy>
            <iyz>-6e-06</iyz>
            <izz>3e-05</izz>
          </inertia>
        </inertial>
        <collision name='right-gripper_v2_1_collision'>
          <pose>-0.019146 0.011906 -0.356167 0 -0 0</pose>
          <geometry>
            <mesh>
              <scale>0.001 0.001 0.001</scale>
              <uri>model://fivedofarmzup_description/meshes/right-gripper_v2_1.stl</uri>
            </mesh>
          </geometry>
          <surface>
            <contact>
              <ode/>
            </contact>
            <friction>
              <ode>
                <mu>0.2</mu>
                <mu2>0.2</mu2>
              </ode>
              <torsional>
                <ode/>
              </torsional>
            </friction>
            <bounce/>
          </surface>
          <max_contacts>10</max_contacts>
        </collision>
        <visual name='right-gripper_v2_1_visual'>
          <pose>-0.019146 0.011906 -0.356167 0 -0 0</pose>
          <geometry>
            <mesh>
              <scale>0.001 0.001 0.001</scale>
              <uri>model://fivedofarmzup_description/meshes/right-gripper_v2_1.stl</uri>
            </mesh>
          </geometry>
          <material>
            <script>
              <name>Gazebo/Blue</name>
              <uri>file://media/materials/scripts/gazebo.material</uri>
            </script>
          </material>
        </visual>
        <self_collide>1</self_collide>
        <gravity>1</gravity>
        <enable_wind>0</enable_wind>
        <kinematic>0</kinematic>
      </link>
      <pose>0 0 0 0 -0 0</pose>
    </model>
    <state world_name='default'>
      <sim_time>3 554000000</sim_time>
      <real_time>27 184375400</real_time>
      <wall_time>1715242631 70525158</wall_time>
      <iterations>3554</iterations>
      <model name='ground_plane'>
        <pose>0 0 0 0 -0 0</pose>
        <scale>1 1 1</scale>
        <link name='link'>
          <pose>0 0 0 0 -0 0</pose>
          <velocity>0 0 0 0 -0 0</velocity>
          <acceleration>0 0 0 0 -0 0</acceleration>
          <wrench>0 0 0 0 -0 0</wrench>
        </link>
      </model>
      <model name='robotic_arm'>
        <pose>-0.044787 0.003227 0.007648 0.113914 0.000431 -1.20576</pose>
        <scale>1 1 1</scale>
        <link name='Gripz_v2_1'>
          <pose>-0.074867 -0.037434 0.214496 -0.088418 0.167782 -1.71413</pose>
          <velocity>-0.339308 -0.001083 -0.085144 2.17076 -1.29759 1.65252</velocity>
          <acceleration>28.899 -37.484 -2.22691 0.877041 1.12437 -1.57481</acceleration>
          <wrench>7.61474 -9.87686 -0.58678 0 -0 0</wrench>
        </link>
        <link name='Servo_Bracket_-_U_Shaped_Defaut_v1_2'>
          <pose>-0.066644 -0.034988 0.07972 0.074533 0.042358 -1.58286</pose>
          <velocity>-0.249721 -0.178405 -0.042617 -2.64444 -1.53782 -1.77753</velocity>
          <acceleration>-30.4446 37.6075 -57.1022 0.108688 -1.03605 1.07228</acceleration>
          <wrench>-8.61155 10.6377 -16.1519 0 -0 0</wrench>
        </link>
        <link name='Servo_Bracket_-_U_Shaped_bis_Defaut_v1_1'>
          <pose>-0.07466 -0.060209 0.094272 1.30333 -0.543486 -2.05445</pose>
          <velocity>-0.220851 -0.15169 0.108561 2.18945 -0.533042 -1.92611</velocity>
          <acceleration>-44.723 34.9934 34.8121 -0.708479 -0.021135 -1.04418</acceleration>
          <wrench>-4.92168 3.85095 3.831 0 -0 0</wrench>
        </link>
        <link name='Standard_Servo__1501MG__v2_3'>
          <pose>-0.140437 -0.012858 0.117889 -1.8334 0.681054 -2.36761</pose>
          <velocity>-0.133523 0.03394 -0.122127 -2.71147 -1.18688 -1.92251</velocity>
          <acceleration>-39.4428 40.8495 54.0287 -0.385093 -0.841793 2.76749</acceleration>
          <wrench>-13.6824 14.1704 18.7422 0 -0 0</wrench>
        </link>
        <link name='Standard_Servo__1501MG__v2_4'>
          <pose>-0.047198 -0.00836 0.125384 -0.085284 0.155947 -1.58366</pose>
          <velocity>-0.119203 -0.134718 -0.054709 2.35157 -1.29094 1.18364</velocity>
          <acceleration>-14.9463 15.4098 7.36615 -1.99639 -1.17582 2.84431</acceleration>
          <wrench>-8.73441 9.00528 4.30469 0 -0 0</wrench>
        </link>
        <link name='base_link'>
          <pose>-0.044787 0.003227 0.007648 0.113914 0.000431 -1.20576</pose>
          <velocity>-0.216511 -0.244145 -0.097796 -2.40506 -0.851434 1.84984</velocity>
          <acceleration>68.0004 -66.3329 -69.8442 -0.428014 -1.55254 -1.81023</acceleration>
          <wrench>28.6526 -27.95 -29.4295 0 -0 0</wrench>
        </link>
        <link name='left-gripper_v3_1'>
          <pose>-0.060281 -0.070048 0.230524 1.6718 0.876757 -0.476455</pose>
          <velocity>-0.391713 0.007482 -0.023273 -2.21386 -0.715686 -1.50914</velocity>
          <acceleration>8.58416 2.41037 -14.2293 0.610125 -0.60775 0.086558</acceleration>
          <wrench>0.213376 0.059914 -0.353698 0 -0 0</wrench>
        </link>
        <link name='right-gripper_v2_1'>
          <pose>-0.043745 -0.053171 0.23264 -1.20192 -0.911161 -1.28108</pose>
          <velocity>-0.433485 -0.045578 -0.040604 -0.906022 -1.11219 -2.26219</velocity>
          <acceleration>-21.3465 4.12807 -21.3939 -2.94179 -1.22022 -0.200252</acceleration>
          <wrench>-0.530611 0.102611 -0.531788 0 -0 0</wrench>
        </link>
      </model>
      <light name='sun'>
        <pose>0 0 10 0 -0 0</pose>
      </light>
    </state>
    <gui fullscreen='0'>
      <camera name='user_camera'>
        <pose>5 -5 2 0 0.275643 2.35619</pose>
        <view_controller>orbit</view_controller>
        <projection_type>perspective</projection_type>
      </camera>
    </gui>
  </world>
</sdf>
